The above exception was the direct cause of the following exception:

Traceback (most recent call last):
  File "/home/b656/.repo/repo/main.py", line 630, in <module>
    _Main(sys.argv[1:])
  File "/home/b656/.repo/repo/main.py", line 604, in _Main
    result = run()
  File "/home/b656/.repo/repo/main.py", line 597, in <lambda>
    run = lambda: repo._Run(name, gopts, argv) or 0
  File "/home/b656/.repo/repo/main.py", line 261, in _Run
    result = cmd.Execute(copts, cargs)
  File "/home/b656/.repo/repo/subcmds/sync.py", line 952, in Execute
    err_checkout = not self._Checkout(all_projects, opt, err_results)
  File "/home/b656/.repo/repo/subcmds/sync.py", line 535, in _Checkout
    if not _ProcessResults(results):
  File "/home/b656/.repo/repo/subcmds/sync.py", line 513, in _ProcessResults
    for (success, project, start, finish) in results:
  File "/usr/lib/python3.6/multiprocessing/pool.py", line 347, in <genexpr>
    return (item for chunk in result for item in chunk)
  File "/usr/lib/python3.6/multiprocessing/pool.py", line 735, in next
    raise value
error.GitError: Cannot initialize work tree for intel/linux-intel-lts.git

